2024-07-04 12:36:03,537 - instabot version: 0.117.0 (bot) - INFO - Instabot version: 0.117.0 Started
2024-07-04 12:36:03,538 - instabot version: 0.117.0 (bot) - DEBUG - Bot imported from /Library/Frameworks/Python.framework/Versions/3.11/lib/python3.11/site-packages/instabot/bot/bot.py
2024-07-04 12:36:03,538 - instabot version: 0.117.0 (api_login) - INFO - Not yet logged in starting: PRE-LOGIN FLOW!
2024-07-04 12:36:04,265 - instabot version: 0.117.0 (api) - WARNING - HTTPSConnectionPool(host='i.instagram.com', port=443): Max retries exceeded with url: /api/v1/accounts/get_prefill_candidates/ (Caused by NewConnectionError('<urllib3.connection.HTTPSConnection object at 0x1041bb390>: Failed to establish a new connection: [Errno 65] No route to host'))
2024-07-04 12:36:04,335 - instabot version: 0.117.0 (api) - WARNING - HTTPSConnectionPool(host='i.instagram.com', port=443): Max retries exceeded with url: /api/v1/qe/sync/ (Caused by NewConnectionError('<urllib3.connection.HTTPSConnection object at 0x1041d18d0>: Failed to establish a new connection: [Errno 65] No route to host'))
2024-07-04 12:36:04,372 - instabot version: 0.117.0 (api) - WARNING - HTTPSConnectionPool(host='i.instagram.com', port=443): Max retries exceeded with url: /api/v1/launcher/sync/ (Caused by NewConnectionError('<urllib3.connection.HTTPSConnection object at 0x1041d3c50>: Failed to establish a new connection: [Errno 65] No route to host'))
2024-07-04 12:36:04,433 - instabot version: 0.117.0 (api) - WARNING - HTTPSConnectionPool(host='i.instagram.com', port=443): Max retries exceeded with url: /api/v1/accounts/contact_point_prefill/ (Caused by NewConnectionError('<urllib3.connection.HTTPSConnection object at 0x1041d6010>: Failed to establish a new connection: [Errno 65] No route to host'))
